Traceback (most recent call last):
  File "<frozen runpy>", line 198, in _run_module_as_main
  File "<frozen runpy>", line 88, in _run_code
  File "/home/roberto/.espressif/python_env/idf5.4_py3.12_env/lib/python3.12/site-packages/esptool/__main__.py", line 9, in <module>
    esptool._main()
  File "/home/roberto/.espressif/python_env/idf5.4_py3.12_env/lib/python3.12/site-packages/esptool/__init__.py", line 1170, in _main
    main()
  File "/home/roberto/.espressif/python_env/idf5.4_py3.12_env/lib/python3.12/site-packages/esptool/__init__.py", line 721, in main
    esp = esp or get_default_connected_device(
                 ^^^^^^^^^^^^^^^^^^^^^^^^^^^^^
  File "/home/roberto/.espressif/python_env/idf5.4_py3.12_env/lib/python3.12/site-packages/esptool/__init__.py", line 1055, in get_default_connected_device
    _esp.connect(before, connect_attempts)
  File "/home/roberto/.espressif/python_env/idf5.4_py3.12_env/lib/python3.12/site-packages/esptool/loader.py", line 703, in connect
    last_error = self._connect_attempt(reset_strategy, mode)
                 ^^^^^^^^^^^^^^^^^^^^^^^^^^^^^^^^^^^^^^^^^^^
  File "/home/roberto/.espressif/python_env/idf5.4_py3.12_env/lib/python3.12/site-packages/esptool/loader.py", line 588, in _connect_attempt
    reset_strategy()  # Reset the chip to bootloader (download mode)
    ^^^^^^^^^^^^^^^^
  File "/home/roberto/.espressif/python_env/idf5.4_py3.12_env/lib/python3.12/site-packages/esptool/reset.py", line 38, in __call__
    self.reset()
  File "/home/roberto/.espressif/python_env/idf5.4_py3.12_env/lib/python3.12/site-packages/esptool/reset.py", line 118, in reset
    self._setRTS(False)
  File "/home/roberto/.espressif/python_env/idf5.4_py3.12_env/lib/python3.12/site-packages/esptool/reset.py", line 58, in _setRTS
    self.port.setRTS(state)
  File "/home/roberto/.espressif/python_env/idf5.4_py3.12_env/lib/python3.12/site-packages/serial/serialutil.py", line 600, in setRTS
    self.rts = value
    ^^^^^^^^
  File "/home/roberto/.espressif/python_env/idf5.4_py3.12_env/lib/python3.12/site-packages/serial/serialutil.py", line 463, in rts
    self._update_rts_state()
  File "/home/roberto/.espressif/python_env/idf5.4_py3.12_env/lib/python3.12/site-packages/serial/serialposix.py", line 708, in _update_rts_state
    fcntl.ioctl(self.fd, TIOCMBIC, TIOCM_RTS_str)
BrokenPipeError: [Errno 32] Broken pipe
CMake Error at run_serial_tool.cmake:66 (message):
  
  /home/roberto/.espressif/python_env/idf5.4_py3.12_env/bin/python;;/home/roberto/esp/esp-idf/components/esptool_py/esptool/esptool.py;--chip;esp32c6
  failed.



